Workbook

Sheet BUP Shift Details Day
A1: BUILD UP // 00 SEP 2021 // SHIFT : 00 // 00:00-00:00HRS
A3: Checked by Supervisor
A6: Name | E6: Staff ID | I6: Signature
A7: Allocation | F7: Staff Performance | O7: Shift & Staff Details
F8: Total ULD | G8: Built | K8: Thru
A9: No | B9: Flight | C9: ETD | D9: DST | E9: Staff | G9: PMC/AMF | H9: ALF/PLA | I9: AKE/AKL | J9: Total | K9: PMC/AMF | L9: ALF/PLA | M9: AKE/AKL | N9: Total | O9: Analysis | Q9: Sr.No | R9: Total Staffs | S9: Staff No | T9: Flight Count | U9: ULD Count | V9: Deployment | W9: Contact | X9: Duty Hours | Y9: Actual Hours
A10: 1 | F10: =J10+N10 -> 0 | J10: =G10+H10+I10 -> 0 | N10: =K10+L10+M10 -> 0 | O10: Built ULD Details | R10: Positionals
A11: 2 | F11: =J11+N11 -> 0 | J11: =G11+H11+I11 -> 0 | N11: =K11+L11+M11 -> 0 | O11: Total PMC | P11: =SUM(G10:G109,G111:G212,G214:G352) -> 188 | Q11: 1 | T11: =COUNTIF($E$10:$E$478,R11) -> 0 | U11: =SUMIFS($F$10:$F$478,$E$10:$E$478,R11) -> 0 | V11: Chaser
A12: 3 | F12: =J12+N12 -> 0 | J12: =G12+H12+I12 -> 0 | N12: =K12+L12+M12 -> 0 | O12: Total ALF | P12: =SUM(H10:H109,H111:H212,H214:H352) -> 15 | Q12: 2 | T12: =COUNTIF($E$10:$E$478,R12) -> 0 | U12: =SUMIFS($F$10:$F$478,$E$10:$E$478,R12) -> 0 | V12: RXS
A13: 4 | F13: =J13+N13 -> 0 | J13: =G13+H13+I13 -> 0 | N13: =K13+L13+M13 -> 0 | O13: Total AKE | P13: =SUM(I10:I109,I111:I212,I214:I352) -> 84 | Q13: 3 | T13: =COUNTIF($E$10:$E$478,R13) -> 0 | U13: =SUMIFS($F$10:$F$478,$E$10:$E$478,R13) -> 0 | V13: CTO
A14: 5 | F14: =J14+N14 -> 0 | J14: =G14+H14+I14 -> 0 | N14: =K14+L14+M14 -> 0 | O14: Total ULD | P14: =SUM(P11:P13) -> 287 | Q14: 4 | T14: =COUNTIF($E$10:$E$478,R14) -> 0 | U14: =SUMIFS($F$10:$F$478,$E$10:$E$478,R14) -> 0 | V14: Screening
A15: 6 | F15: =J15+N15 -> 0 | J15: =G15+H15+I15 -> 0 | N15: =K15+L15+M15 -> 0 | O15: Thru ULD Details | Q15: 5 | T15: =COUNTIF($E$10:$E$478,R15) -> 0 | U15: =SUMIFS($F$10:$F$478,$E$10:$E$478,R15) -> 0 | V15: Screening
A16: 7 | F16: =J16+N16 -> 0 | J16: =G16+H16+I16 -> 0 | N16: =K16+L16+M16 -> 0 | O16: Total PMC | P16: =SUM(K10:K109,K111:K212,K214:K352) -> 16 | Q16: 6 | T16: =COUNTIF($E$10:$E$478,R16) -> 0 | U16: =SUMIFS($F$10:$F$478,$E$10:$E$478,R16) -> 0 | V16: Screening
A17: 8 | F17: =J17+N17 -> 0 | J17: =G17+H17+I17 -> 0 | N17: =K17+L17+M17 -> 0 | O17: Total ALF | P17: =SUM(L10:L109,L111:L212,L214:L352) -> 0 | Q17: 7 | T17: =COUNTIF($E$10:$E$478,R17) -> 0 | U17: =SUMIFS($F$10:$F$478,$E$10:$E$478,R17) -> 0 | V17: Screening Support
A18: 9 | F18: =J18+N18 -> 0 | J18: =G18+H18+I18 -> 0 | N18: =K18+L18+M18 -> 0 | O18: Total AKE | P18: =SUM(M10:M109,M111:M212,M214:M352) -> 0 | Q18: 8 | T18: =COUNTIF($E$10:$E$478,R18) -> 0 | U18: =SUMIFS($F$10:$F$478,$E$10:$E$478,R18) -> 0 | V18: DG Support
A19: 10 | F19: =J19+N19 -> 0 | J19: =G19+H19+I19 -> 0 | N19: =K19+L19+M19 -> 0 | O19: Total ULD | P19: =SUM(P16:P18) -> 16 | Q19: 9 | T19: =COUNTIF($E$10:$E$478,R19) -> 0 | U19: =SUMIFS($F$10:$F$478,$E$10:$E$478,R19) -> 0 | V19: Floor Support
A20: 11 | F20: =J20+N20 -> 0 | J20: =G20+H20+I20 -> 0 | N20: =K20+L20+M20 -> 0 | O20: Total ULD Details | Q20: 10 | T20: =COUNTIF($E$10:$E$478,R20) -> 0 | U20: =SUMIFS($F$10:$F$478,$E$10:$E$478,R20) -> 0 | V20: Chaser Support
A21: 12 | F21: =J21+N21 -> 0 | J21: =G21+H21+I21 -> 0 | N21: =K21+L21+M21 -> 0 | O21: Total PMC | P21: =SUM(G10:G109,G111:G212,G214:G352,K10:K109,K111:K212,K214:K352) -> 204 | Q21: 11 | T21: =COUNTIF($E$10:$E$478,R21) -> 0 | U21: =SUMIFS($F$10:$F$478,$E$10:$E$478,R21) -> 0 | V21: Cross Utilized
A22: 13 | F22: =J22+N22 -> 0 | J22: =G22+H22+I22 -> 0 | N22: =K22+L22+M22 -> 0 | O22: Total ALF | P22: =SUM(H10:H109,L10:L109,H111:H212,L111:L212,H214:H352,L214:L352) -> 15 | Q22: 12 | T22: =COUNTIF($E$10:$E$478,R22) -> 0 | U22: =SUMIFS($F$10:$F$478,$E$10:$E$478,R22) -> 0 | V22: RXS Support
A23: 14 | F23: =J23+N23 -> 0 | J23: =G23+H23+I23 -> 0 | N23: =K23+L23+M23 -> 0 | O23: Total AKE | P23: =SUM(I10:I109,M10:M109,M111:M212,I111:I212,I214:I352,M214:M352) -> 84 | Q23: 13 | T23: =COUNTIF($E$10:$E$478,R23) -> 0 | U23: =SUMIFS($F$10:$F$478,$E$10:$E$478,R23) -> 0 | V23: CTO Support
A24: 15 | F24: =J24+N24 -> 0 | J24: =G24+H24+I24 -> 0 | N24: =K24+L24+M24 -> 0 | O24: Total ULD | P24: =SUM(P21:P23) -> 303 | Q24: Total | T24: =SUM(T11:T23) -> 0 | U24: =SUM(U11:U23) -> 0 | V24: =COUNT(X11:X23) -> 0
A25: 16 | F25: =J25+N25 -> 0 | J25: =G25+H25+I25 -> 0 | N25: =K25+L25+M25 -> 0 | O25: Head Count | Q25: EK On Floor & Support Team
A26: 17 | F26: =J26+N26 -> 0 | J26: =G26+H26+I26 -> 0 | N26: =K26+L26+M26 -> 0 | O26: Pos & Supp | P26: =COUNT(X11:X24) -> 0 | Q26: 1 | T26: =COUNTIF($E$10:$E$478,R26) -> 0 | U26: =SUMIFS($F$10:$F$478,$E$10:$E$478,R26) -> 0
A27: 18 | F27: =J27+N27 -> 0 | J27: =G27+H27+I27 -> 0 | N27: =K27+L27+M27 -> 0 | O27: Shift | P27: =COUNTIF(V26:V340,"*Shift*") -> 0 | Q27: 2 | T27: =COUNTIF($E$10:$E$478,R27) -> 0 | U27: =SUMIFS($F$10:$F$478,$E$10:$E$478,R27) -> 0
A28: 19 | F28: =J28+N28 -> 0 | J28: =G28+H28+I28 -> 0 | N28: =K28+L28+M28 -> 0 | O28: TG | P28: =COUNTIF(V26:V340,"*TG*") -> 0 | Q28: 3 | T28: =COUNTIF($E$10:$E$478,R28) -> 0 | U28: =SUMIFS($F$10:$F$478,$E$10:$E$478,R28) -> 0
A29: 20 | F29: =J29+N29 -> 0 | J29: =G29+H29+I29 -> 0 | N29: =K29+L29+M29 -> 0 | O29: DL | P29: =COUNTIF(V26:V340,"*DL*") -> 0 | Q29: 4 | T29: =COUNTIF($E$10:$E$478,R29) -> 0 | U29: =SUMIFS($F$10:$F$478,$E$10:$E$478,R29) -> 0
A30: 21 | F30: =J30+N30 -> 0 | J30: =G30+H30+I30 -> 0 | N30: =K30+L30+M30 -> 0 | O30: OT | P30: =COUNTIF(V26:V340,"*OT*") -> 0 | Q30: 5 | T30: =COUNTIF($E$10:$E$478,R30) -> 0 | U30: =SUMIFS($F$10:$F$478,$E$10:$E$478,R30) -> 0
A31: 22 | F31: =J31+N31 -> 0 | J31: =G31+H31+I31 -> 0 | N31: =K31+L31+M31 -> 0 | O31: DP | P31: =COUNTIF(V26:V340,"*DP*") -> 0 | Q31: 6 | T31: =COUNTIF($E$10:$E$478,R31) -> 0 | U31: =SUMIFS($F$10:$F$478,$E$10:$E$478,R31) -> 0
A32: 23 | F32: =J32+N32 -> 0 | J32: =G32+H32+I32 -> 0 | N32: =K32+L32+M32 -> 0 | O32: Total | P32: =SUM(P26:P31) -> 0 | Q32: 7 | T32: =COUNTIF($E$10:$E$478,R32) -> 0 | U32: =SUMIFS($F$10:$F$478,$E$10:$E$478,R32) -> 0
A33: 24 | F33: =J33+N33 -> 0 | J33: =G33+H33+I33 -> 0 | N33: =K33+L33+M33 -> 0 | O33: Supervsiors | Q33: 8 | T33: =COUNTIF($E$10:$E$478,R33) -> 0 | U33: =SUMIFS($F$10:$F$478,$E$10:$E$478,R33) -> 0
A34: 25 | F34: =J34+N34 -> 0 | J34: =G34+H34+I34 -> 0 | N34: =K34+L34+M34 -> 0 | P34: 0566558712 | Q34: 9 | T34: =COUNTIF($E$10:$E$478,R34) -> 0 | U34: =SUMIFS($F$10:$F$478,$E$10:$E$478,R34) -> 0
A35: 26 | F35: =J35+N35 -> 0 | J35: =G35+H35+I35 -> 0 | N35: =K35+L35+M35 -> 0 | P35: 0562165753 | Q35: 10 | T35: =COUNTIF($E$10:$E$478,R35) -> 0 | U35: =SUMIFS($F$10:$F$478,$E$10:$E$478,R35) -> 0
A36: 27 | F36: =J36+N36 -> 0 | J36: =G36+H36+I36 -> 0 | N36: =K36+L36+M36 -> 0 | P36: 0562165751 | Q36: 11 | T36: =COUNTIF($E$10:$E$478,R36) -> 0 | U36: =SUMIFS($F$10:$F$478,$E$10:$E$478,R36) -> 0
A37: 28 | F37: =J37+N37 -> 0 | J37: =G37+H37+I37 -> 0 | N37: =K37+L37+M37 -> 0 | Q37: 12 | T37: =COUNTIF($E$10:$E$478,R37) -> 0 | U37: =SUMIFS($F$10:$F$478,$E$10:$E$478,R37) -> 0
A38: 29 | F38: =J38+N38 -> 0 | J38: =G38+H38+I38 -> 0 | N38: =K38+L38+M38 -> 0 | Q38: 13 | T38: =COUNTIF($E$10:$E$478,R38) -> 0 | U38: =SUMIFS($F$10:$F$478,$E$10:$E$478,R38) -> 0
A39: 30 | F39: =J39+N39 -> 0 | J39: =G39+H39+I39 -> 0 | N39: =K39+L39+M39 -> 0 | Q39: 14 | T39: =COUNTIF($E$10:$E$478,R39) -> 0 | U39: =SUMIFS($F$10:$F$478,$E$10:$E$478,R39) -> 0
A40: 31 | F40: =J40+N40 -> 0 | J40: =G40+H40+I40 -> 0 | N40: =K40+L40+M40 -> 0 | O40: Shift Efficiency | Q40: 15 | T40: =COUNTIF($E$10:$E$478,R40) -> 0 | U40: =SUMIFS($F$10:$F$478,$E$10:$E$478,R40) -> 0
A41: 32 | F41: =J41+N41 -> 0 | J41: =G41+H41+I41 -> 0 | N41: =K41+L41+M41 -> 0 | O41: Total ULD | P41: =P24 -> 303 | Q41: 16 | T41: =COUNTIF($E$10:$E$478,R41) -> 0 | U41: =SUMIFS($F$10:$F$478,$E$10:$E$478,R41) -> 0
A42: 33 | F42: =J42+N42 -> 0 | J42: =G42+H42+I42 -> 0 | N42: =K42+L42+M42 -> 0 | O42: Total Hours | P42: =SUM(X11:X23,X26:X95) -> 0 | Q42: 17 | T42: =COUNTIF($E$10:$E$478,R42) -> 0 | U42: =SUMIFS($F$10:$F$478,$E$10:$E$478,R42) -> 0
A43: 34 | F43: =J43+N43 -> 0 | J43: =G43+H43+I43 -> 0 | N43: =K43+L43+M43 -> 0 | O43: Efficiency | P43: =P41/P42 -> #DIV/0! | Q43: 18 | T43: =COUNTIF($E$10:$E$478,R43) -> 0 | U43: =SUMIFS($F$10:$F$478,$E$10:$E$478,R43) -> 0
...

Sheet BUP Shift Details Night
A1: BUILD UP // 25-NOV-2025 // SHIFT : 01 // 21:00-09:00HRS
A3: Checked by Supervisor
A5: NADEEM | E5: S379571 | J5: NADEEM
A6: Name | E6: Staff ID | I6: Signature
A7: Allocation | F7: Staff Performance | O7: Shift & Staff Details
F8: Total ULD | G8: Built | K8: Thru
A9: No | B9: Flight | C9: ETD | D9: DST | E9: Staff | G9: PMC/AMF | H9: ALF/PLA | I9: AKE/AKL | J9: Total | K9: PMC/AMF | L9: ALF/PLA | M9: AKE/AKL | N9: Total | O9: ULD Analysis | Q9: Sr.No | R9: Total Staffs | S9: Staff No | T9: Flight Count | U9: ULD Count | V9: Deployment | W9: Contact | X9: Duty Hours | Y9: Actual Hours
A10: 1 | B10: 0801 | C10: 00:15 | D10: JED | E10: NABIN | F10: =J10+N10 -> 2 | G10: 0 | H10: 0 | I10: 2 | J10: =G10+H10+I10 -> 2 | N10: =K10+L10+M10 -> 0 | O10: Built ULD Details | R10: Positionals
A11: 2 | B11: 0977 | C11: 01:15 | D11: IKA | E11: LOADING OVER | F11: =J11+N11 -> 0 | G11: 0 | H11: 0 | I11: 0 | J11: =G11+H11+I11 -> 0 | N11: =K11+L11+M11 -> 0 | O11: Total PMC | P11: =SUM(G10:G109,G111:G260,G262:G381) -> 484 | Q11: 1 | R11: SALIN | S11: 495336 | T11: =COUNTIF($E$10:$E$565,R11) -> 0 | U11: =SUMIFS($F$10:$F$565,$E$10:$E$565,R11) -> 0 | V11: Chaser | X11: 12 | Y11: 12
A12: 3 | B12: 0853 | C12: 01:25 | D12: KWI | E12: FARHAN | F12: =J12+N12 -> 2 | G12: 1 | H12: 0 | I12: 1 | J12: =G12+H12+I12 -> 2 | N12: =K12+L12+M12 -> 0 | O12: Total ALF | P12: =SUM(H10:H109,H111:H260,H262:H381) -> 69 | Q12: 2 | R12: MARK | S12: 418664 | T12: =COUNTIF($E$10:$E$565,R12) -> 0 | U12: =SUMIFS($F$10:$F$565,$E$10:$E$565,R12) -> 0 | V12: RXS | X12: 12 | Y12: 12
A13: 4 | B13: 0815 | C13: 01:25 | D13: RUH | E13: NABIN | F13: =J13+N13 -> 2 | G13: 1 | H13: 0 | I13: 1 | J13: =G13+H13+I13 -> 2 | N13: =K13+L13+M13 -> 0 | O13: Total AKE | P13: =SUM(I10:I109,I111:I260,I262:I381) -> 322 | Q13: 3 | R13: ALVIN | S13: 391963 | T13: =COUNTIF($E$10:$E$565,R13) -> 0 | U13: =SUMIFS($F$10:$F$565,$E$10:$E$565,R13) -> 0 | V13: CTO | X13: 12 | Y13: 12
A14: 5 | B14: 0582 | C14: 01:55 | D14: DAC | E14: LOADING OVER | F14: =J14+N14 -> 0 | G14: 0 | H14: 0 | I14: 0 | J14: =G14+H14+I14 -> 0 | N14: =K14+L14+M14 -> 0 | O14: Total ULD | P14: =SUM(P11:P13) -> 875 | Q14: 4 | R14: JITHIN | S14: 433752 | T14: =COUNTIF($E$10:$E$565,R14) -> 0 | U14: =SUMIFS($F$10:$F$565,$E$10:$E$565,R14) -> 0 | V14: Screening | X14: 12 | Y14: 12
A15: 6 | B15: 0570 | C15: 02:00 | D15: CCU | E15: LOADING OVER | F15: =J15+N15 -> 0 | G15: 0 | H15: 0 | I15: 0 | J15: =G15+H15+I15 -> 0 | N15: =K15+L15+M15 -> 0 | O15: Thru ULD Details | Q15: 5 | R15: MANU | S15: 433740 | T15: =COUNTIF($E$10:$E$565,R15) -> 1 | U15: =SUMIFS($F$10:$F$565,$E$10:$E$565,R15) -> 12 | V15: Screening | X15: 12 | Y15: 12
A16: 7 | B16: 0414 | C16: 02:00 | D16: SYD | E16: LOADING OVER | F16: =J16+N16 -> 0 | G16: 0 | H16: 0 | I16: 0 | J16: =G16+H16+I16 -> 0 | N16: =K16+L16+M16 -> 0 | O16: Total PMC | P16: =SUM(K10:K109,K111:K260,K262:K381) -> 16 | Q16: 6 | R16: DAVID | S16: 439111 | T16: =COUNTIF($E$10:$E$565,R16) -> 0 | U16: =SUMIFS($F$10:$F$565,$E$10:$E$565,R16) -> 0 | V16: CTO Support | X16: 12 | Y16: 12
A17: 8 | B17: 0440 | C17: 02:00 | D17: ADL | E17: LOADING OVER | F17: =J17+N17 -> 0 | G17: 0 | H17: 0 | I17: 0 | J17: =G17+H17+I17 -> 0 | N17: =K17+L17+M17 -> 0 | O17: Total ALF | P17: =SUM(L10:L109,L111:L260,L262:L381) -> 0 | Q17: 7 | T17: =COUNTIF($E$10:$E$565,R17) -> 0 | U17: =SUMIFS($F$10:$F$565,$E$10:$E$565,R17) -> 0 | V17: Screening Support
A18: 9 | B18: 0165 | C18: 02:10 | D18: DUB | E18: LOADING OVER | F18: =J18+N18 -> 0 | G18: 0 | H18: 0 | I18: 0 | J18: =G18+H18+I18 -> 0 | N18: =K18+L18+M18 -> 0 | O18: Total AKE | P18: =SUM(M10:M109,M111:M260,M262:M381) -> 0 | Q18: 8 | T18: =COUNTIF($E$10:$E$565,R18) -> 0 | U18: =SUMIFS($F$10:$F$565,$E$10:$E$565,R18) -> 0 | V18: DG Support
A19: 10 | B19: 0213 | C19: 02:15 | D19: MIA-BOG | E19: MARIO | F19: =J19+N19 -> 1 | G19: 0 | H19: 0 | I19: 1 | J19: =G19+H19+I19 -> 1 | N19: =K19+L19+M19 -> 0 | O19: Total ULD | P19: =SUM(P16:P18) -> 16 | Q19: 9 | T19: =COUNTIF($E$10:$E$565,R19) -> 0 | U19: =SUMIFS($F$10:$F$565,$E$10:$E$565,R19) -> 0 | V19: Floor Support
A20: 11 | B20: 0866 | C20: 02:15 | D20: MCT | E20: BIR | F20: =J20+N20 -> 2 | G20: 1 | H20: 0 | I20: 1 | J20: =G20+H20+I20 -> 2 | N20: =K20+L20+M20 -> 0 | O20: Total ULD Details | Q20: 10 | T20: =COUNTIF($E$10:$E$565,R20) -> 0 | U20: =SUMIFS($F$10:$F$565,$E$10:$E$565,R20) -> 0 | V20: Chaser Support
A21: 12 | B21: 0823 | C21: 02:20 | D21: DMM | E21: VISHWA | F21: =J21+N21 -> 1 | G21: 1 | H21: 0 | I21: 0 | J21: =G21+H21+I21 -> 1 | N21: =K21+L21+M21 -> 0 | O21: Total PMC | P21: =SUM(G10:G109,G111:G260,G262:G381,K10:K109,K111:K260,K262:K381) -> 500 | Q21: 11 | T21: =COUNTIF($E$10:$E$565,R21) -> 0 | U21: =SUMIFS($F$10:$F$565,$E$10:$E$565,R21) -> 0 | V21: Photo Support
A22: 13 | B22: 0231 | C22: 02:25 | D22: IAD | E22: LOADING OVER | F22: =J22+N22 -> 0 | G22: 0 | H22: 0 | I22: 0 | J22: =G22+H22+I22 -> 0 | N22: =K22+L22+M22 -> 0 | O22: Total ALF | P22: =SUM(H10:H109,L10:L109,H111:H260,L111:L260,H262:H381,L262:L381) -> 69 | Q22: 12 | T22: =COUNTIF($E$10:$E$565,R22) -> 0 | U22: =SUMIFS($F$10:$F$565,$E$10:$E$565,R22) -> 0 | V22: RXS Support
A23: 14 | B23: 0701 | C23: 02:25 | D23: MRU | E23: RAJU | F23: =J23+N23 -> 2 | G23: 1 | H23: 1 | I23: 0 | J23: =G23+H23+I23 -> 2 | N23: =K23+L23+M23 -> 0 | O23: Total AKE | P23: =SUM(I10:I109,M10:M109,M111:M260,I111:I260,I262:I381,M262:M381) -> 322 | Q23: 13 | T23: =COUNTIF($E$10:$E$565,R23) -> 0 | U23: =SUMIFS($F$10:$F$565,$E$10:$E$565,R23) -> 0 | V23: CTO Support
A24: 15 | B24: 0656 | C24: 02:30 | D24: MLE | E24: JOHN | F24: =J24+N24 -> 2 | G24: 1 | H24: 1 | I24: 0 | J24: =G24+H24+I24 -> 2 | N24: =K24+L24+M24 -> 0 | O24: Total ULD | P24: =SUM(P21:P23) -> 891 | Q24: Total | T24: =SUM(T11:T23) -> 1 | U24: =SUM(U11:U23) -> 12 | V24: =COUNT(X11:X23) -> 6
A25: 16 | B25: 0348 | C25: 02:30 | D25: SIN-KTI | E25: BIR | F25: =J25+N25 -> 1 | G25: 0 | H25: 0 | I25: 1 | J25: =G25+H25+I25 -> 1 | N25: =K25+L25+M25 -> 0 | O25: Head Count | Q25: EK On Floor & Support Team
A26: 17 | B26: 0203 | C26: 02:35 | D26: JFK | E26: MARIO | F26: =J26+N26 -> 1 | G26: 1 | H26: 0 | I26: 0 | J26: =G26+H26+I26 -> 1 | N26: =K26+L26+M26 -> 0 | O26: Pos & Supp | P26: =COUNT(X11:X23) -> 6 | Q26: 1 | R26: BIR | S26: 487090 | T26: =COUNTIF($E$10:$E$565,R26) -> 8 | U26: =SUMIFS($F$10:$F$565,$E$10:$E$565,R26) -> 32 | V26: SHIFT | X26: 12 | Y26: 12
A27: 18 | B27: 0650 | C27: 02:35 | D27: CMB | E27: GIREESH | F27: =J27+N27 -> 1 | G27: 1 | H27: 0 | I27: 0 | J27: =G27+H27+I27 -> 1 | N27: =K27+L27+M27 -> 0 | O27: Shift | P27: =COUNTIF(V26:V428,"*Shift*") -> 16 | Q27: 2 | R27: FARHAN | S27: 427204 | T27: =COUNTIF($E$10:$E$565,R27) -> 9 | U27: =SUMIFS($F$10:$F$565,$E$10:$E$565,R27) -> 27 | V27: SHIFT | X27: 12 | Y27: 12
A28: 19 | B28: 0021 | C28: 02:40 | D28: MAN | E28: RAJU | F28: =J28+N28 -> 4 | G28: 3 | H28: 0 | I28: 1 | J28: =G28+H28+I28 -> 4 | N28: =K28+L28+M28 -> 0 | O28: TG | P28: =COUNTIF(V26:V428,"*TG*") -> 13 | Q28: 3 | R28: GIREESH | S28: 442663 | T28: =COUNTIF($E$10:$E$565,R28) -> 7 | U28: =SUMIFS($F$10:$F$565,$E$10:$E$565,R28) -> 24 | V28: SHIFT | X28: 12 | Y28: 12
A29: 20 | B29: 0705 | C29: 02:40 | D29: SEZ | E29: GIREESH | F29: =J29+N29 -> 1 | G29: 1 | H29: 0 | I29: 0 | J29: =G29+H29+I29 -> 1 | N29: =K29+L29+M29 -> 0 | O29: DL | P29: =COUNTIF(V26:V428,"*DL*") -> 6 | Q29: 4 | R29: KIMANI | S29: 618485 | T29: =COUNTIF($E$10:$E$565,R29) -> 4 | U29: =SUMIFS($F$10:$F$565,$E$10:$E$565,R29) -> 27 | V29: SHIFT | X29: 12 | Y29: 12
A30: 21 | B30: 0221 | C30: 02:40 | D30: DFW | E30: LOADING OVER | F30: =J30+N30 -> 0 | G30: 0 | H30: 0 | I30: 0 | J30: =G30+H30+I30 -> 0 | N30: =K30+L30+M30 -> 0 | O30: OT | P30: =COUNTIF(V26:V428,"*OT*") -> 3 | Q30: 5 | R30: NABIN | S30: 482260 | T30: =COUNTIF($E$10:$E$565,R30) -> 9 | U30: =SUMIFS($F$10:$F$565,$E$10:$E$565,R30) -> 30 | V30: SHIFT | X30: 12 | Y30: 12
A31: 22 | B31: 0243 | C31: 02:45 | D31: YUL | E31: LOADING OVER | F31: =J31+N31 -> 0 | G31: 0 | H31: 0 | I31: 0 | J31: =G31+H31+I31 -> 0 | N31: =K31+L31+M31 -> 0 | O31: DP | P31: =COUNTIF(V26:V429,"*DP*") -> 1 | Q31: 6 | R31: REJITH | S31: 178205 | T31: =COUNTIF($E$10:$E$565,R31) -> 7 | U31: =SUMIFS($F$10:$F$565,$E$10:$E$565,R31) -> 28 | V31: SHIFT | X31: 12 | Y31: 12
A32: 23 | B32: 0530 | C32: 02:45 | D32: COK | E32: SALMAN | F32: =J32+N32 -> 6 | G32: 4 | H32: 0 | I32: 2 | J32: =G32+H32+I32 -> 6 | N32: =K32+L32+M32 -> 0 | O32: Total | P32: =SUM(P26:P31) -> 45 | Q32: 7 | R32: ALEXEEV | S32: 435773 | T32: =COUNTIF($E$10:$E$565,R32) -> 3 | U32: =SUMIFS($F$10:$F$565,$E$10:$E$565,R32) -> 23 | V32: SHIFT | X32: 12 | Y32: 12
A33: 24 | B33: 0420 | C33: 02:45 | D33: PER | E33: LOADING OVER | F33: =J33+N33 -> 0 | G33: 0 | H33: 0 | I33: 0 | J33: =G33+H33+I33 -> 0 | N33: =K33+L33+M33 -> 0 | O33: Supervsiors | Q33: 8 | R33: ANDREW | S33: 618846 | T33: =COUNTIF($E$10:$E$565,R33) -> 4 | U33: =SUMIFS($F$10:$F$565,$E$10:$E$565,R33) -> 11 | V33: SHIFT | X33: 12 | Y33: 12
A34: 25 | B34: 0338 | C34: 02:50 | D34: CEB-CRK | E34: LOADING OVER | F34: =J34+N34 -> 0 | G34: 0 | H34: 0 | I34: 0 | J34: =G34+H34+I34 -> 0 | N34: =K34+L34+M34 -> 0 | O34: ZAIN | P34: 0566558712 | Q34: 9 | R34: BRYAN | S34: 619795 | T34: =COUNTIF($E$10:$E$565,R34) -> 4 | U34: =SUMIFS($F$10:$F$565,$E$10:$E$565,R34) -> 17 | V34: SHIFT | X34: 12 | Y34: 12
A35: 26 | B35: 0544 | C35: 02:50 | D35: MAA | E35: REJITH | F35: =J35+N35 -> 2 | G35: 1 | H35: 0 | I35: 1 | J35: =G35+H35+I35 -> 2 | N35: =K35+L35+M35 -> 0 | O35: NADEEM | P35: 0561280474 | Q35: 10 | R35: MARIO | S35: 618692 | T35: =COUNTIF($E$10:$E$565,R35) -> 6 | U35: =SUMIFS($F$10:$F$565,$E$10:$E$565,R35) -> 26 | V35: SHIFT | X35: 12 | Y35: 12
A36: 27 | B36: 0011 | C36: 02:50 | D36: LGW | E36: GIREESH | F36: =J36+N36 -> 5 | G36: 3 | H36: 0 | I36: 2 | J36: =G36+H36+I36 -> 5 | N36: =K36+L36+M36 -> 0 | O36: BHUWAN | P36: 0562165751 | Q36: 11 | R36: SAMUEL | S36: 618713 | T36: =COUNTIF($E$10:$E$565,R36) -> 4 | U36: =SUMIFS($F$10:$F$565,$E$10:$E$565,R36) -> 9 | V36: SHIFT | X36: 12 | Y36: 12
A37: 28 | B37: 0430 | C37: 02:50 | D37: BNE | E37: NABIN | F37: =J37+N37 -> 1 | G37: 1 | H37: 0 | I37: 0 | J37: =G37+H37+I37 -> 1 | N37: =K37+L37+M37 -> 0 | O37: KHALIQ | P37: 0566523685 | Q37: 12 | R37: VISHWA | S37: 607321 | T37: =COUNTIF($E$10:$E$565,R37) -> 9 | U37: =SUMIFS($F$10:$F$565,$E$10:$E$565,R37) -> 16 | V37: SHIFT | X37: 12 | Y37: 12
A38: 29 | B38: 0408 | C38: 02:55 | D38: MEL | E38: LOADING OVER | F38: =J38+N38 -> 0 | G38: 0 | H38: 0 | I38: 0 | J38: =G38+H38+I38 -> 0 | N38: =K38+L38+M38 -> 0 | O38: RANJIT | P38: 0566523140 | Q38: 13 | R38: WAHAB | S38: 72763 | T38: =COUNTIF($E$10:$E$565,R38) -> 6 | U38: =SUMIFS($F$10:$F$565,$E$10:$E$565,R38) -> 23 | V38: SHIFT | X38: 12 | Y38: 12
A39: 30 | B39: 0318 | C39: 02:55 | D39: NRT | E39: JOHN | F39: =J39+N39 -> 2 | G39: 0 | H39: 1 | I39: 1 | J39: =G39+H39+I39 -> 2 | N39: =K39+L39+M39 -> 0 | O39: JOSIAH | P39: 0562165753 | Q39: 14 | R39: ZAHID | S39: 401648 | T39: =COUNTIF($E$10:$E$565,R39) -> 5 | U39: =SUMIFS($F$10:$F$565,$E$10:$E$565,R39) -> 20 | V39: SHIFT | X39: 12 | Y39: 12
A40: 31 | B40: 0378 | C40: 03:00 | D40: HKT | E40: LOADING OVER | F40: =J40+N40 -> 0 | G40: 0 | H40: 0 | I40: 0 | J40: =G40+H40+I40 -> 0 | N40: =K40+L40+M40 -> 0 | O40: Shift Efficiency | Q40: 15 | R40: ERIC | S40: 434671 | T40: =COUNTIF($E$10:$E$565,R40) -> 4 | U40: =SUMIFS($F$10:$F$565,$E$10:$E$565,R40) -> 21 | V40: SHIFT | X40: 8 | Y40: 8
A41: 32 | B41: 0316 | C41: 03:05 | D41: KIX | E41: LOADING OVER | F41: =J41+N41 -> 0 | G41: 0 | H41: 0 | I41: 0 | J41: =G41+H41+I41 -> 0 | N41: =K41+L41+M41 -> 0 | O41: Total ULD | P41: =P24 -> 891 | Q41: 16 | R41: MATRIKA | S41: 495554 | T41: =COUNTIF($E$10:$E$565,R41) -> 4 | U41: =SUMIFS($F$10:$F$565,$E$10:$E$565,R41) -> 26 | V41: SHIFT | X41: 8 | Y41: 8
A42: 33 | B42: 0219 | C42: 03:05 | D42: MCO | E42: LOADING OVER | F42: =J42+N42 -> 0 | G42: 0 | H42: 0 | I42: 0 | J42: =G42+H42+I42 -> 0 | N42: =K42+L42+M42 -> 0 | O42: Total Hours | P42: =SUM(X11:X24,X26:X95) -> 506 | Q42: 17 | R42: FELIX | S42: 618108 | T42: =COUNTIF($E$10:$E$565,R42) -> 4 | U42: =SUMIFS($F$10:$F$565,$E$10:$E$565,R42) -> 25 | V42: OT | X42: 12 | Y42: 12
...

Sheet Sheet1

Sheet Early Morning Report
A1: First Wave Flights | B1: ETD | C1: ROUTING | D1: STAFF | E1: THRU PMC/AMF | F1: THRU ALF/PLA | G1: THRU AKE/AKL | H1: Built PMC/AMF | I1: Built ALF/PLA | J1: Built AKE/AKL | K1: ULD BUILT | L1: ULD PENDING | M1: REMARKS
K2: =SUM(E2:J2) -> 0
K3: =SUM(E3:J3) -> 0
K4: =SUM(E4:J4) -> 0
K5: =SUM(E5:J5) -> 0
K6: =SUM(E6:J6) -> 0
K7: =SUM(E7:J7) -> 0
K8: =SUM(E8:J8) -> 0
K9: =SUM(E9:J9) -> 0
K10: =SUM(E10:J10) -> 0
K11: =SUM(E11:J11) -> 0
K12: =SUM(E12:J12) -> 0
K13: =SUM(E13:J13) -> 0
... K51: =SUM(E51:J51) -> 0
A52: Total | E52: =SUM(E2:E51) -> 0 | F52: =SUM(F2:F51) -> 0 | G52: =SUM(G2:G51) -> 0 | H52: =SUM(H2:H51) -> 0 | I52: =SUM(I2:I51) -> 0 | J52: =SUM(J2:J51) -> 0 | K52: =SUM(K2:K51) -> 0 | L52: =SUM(L2:L51) -> 0
A53: Second Wave Flights | B53: ETD | C53: ROUTING | D53: STAFF | E53: THRU PMC/AMF | F53: THRU ALF/PLA | G53: THRU AKE/AKL | H53: Built PMC/AMF | I53: Built ALF/PLA | J53: Built AKE/AKL | K53: ULD BUILT | L53: ULD PENDING | M53: REMARKS
K54: =SUM(E54:J54) -> 0
K55: =SUM(E55:J55) -> 0
K56: =SUM(E56:J56) -> 0
K57: =SUM(E57:J57) -> 0
K58: =SUM(E58:J58) -> 0
K59: =SUM(E59:J59) -> 0
K60: =SUM(E60:J60) -> 0
K61: =SUM(E61:J61) -> 0
K62: =SUM(E62:J62) -> 0
K63: =SUM(E63:J63) -> 0
K64: =SUM(E64:J64) -> 0
K65: =SUM(E65:J65) -> 0
... K104: =SUM(E104:J104) -> 0
A105: Total | E105: =SUM(E54:E104) -> 0 | F105: =SUM(F54:F104) -> 0 | G105: =SUM(G54:G104) -> 0 | H105: =SUM(H54:H104) -> 0 | I105: =SUM(I54:I104) -> 0 | J105: =SUM(J54:J104) -> 0 | K105: =SUM(K54:K104) -> 0 | L105: =SUM(L54:L104) -> 0

Sheet Adv Report
A1: ADVANCE UNITS | O1: BONUS UNITS
A2: FLTS | B2: STAFF | C2: THRU ULDS | F2: BUILT ULDS | I2: TOT | J2: PENDING UNITS | M2: TOT | O2: FLTS | P2: STAFF | Q2: THRU ULDS | T2: BUILT ULDS | W2: TOT | X2: PENDING UNITS | AA2: TOT
C3: PMC | D3: ALF | E3: AKE | F3: PMC | G3: ALF | H3: AKE | J3: PMC | K3: ALF | L3: AKE | Q3: PMC | R3: ALF | S3: AKE | T3: PMC | U3: ALF | V3: AKE | X3: PMC | Y3: ALF | Z3: AKE
A4: 0572 | B4: REJITH | F4: 2 | G4: 0 | H4: 0 | I4: =SUM(C4:H4) -> 2 | M4: =SUM(J4:L4) -> 0 | O4: 0005 | P4: DAWOOD | T4: 4 | U4: 0 | V4: 3 | W4: =SUM(Q4:V4) -> 7 | AA4: =SUM(X4:Z4) -> 0
A5: 0502 | B5: WAHAB | F5: 2 | G5: 1 | H5: 0 | I5: =SUM(C5:H5) -> 3 | M5: =SUM(J5:L5) -> 0 | O5: 0648 | P5: MYO | T5: 0 | U5: 0 | V5: 1 | W5: =SUM(Q5:V5) -> 1 | AA5: =SUM(X5:Z5) -> 0
A6: 0566 | B6: SALMAN | F6: 6 | G6: 1 | H6: 0 | I6: =SUM(C6:H6) -> 7 | M6: =SUM(J6:L6) -> 0 | O6: 0131 | P6: SALMAN | T6: 1 | U6: 0 | V6: 0 | W6: =SUM(Q6:V6) -> 1 | AA6: =SUM(X6:Z6) -> 0
A7: 0041 | B7: DAWOOD | C7: 2 | D7: 0 | E7: 0 | F7: 4 | G7: 1 | H7: 1 | I7: =SUM(C7:H7) -> 8 | M7: =SUM(J7:L7) -> 0 | O7: 0584 | P7: FARHAN | Q7: 2 | R7: 0 | S7: 0 | T7: 2 | U7: 0 | V7: 4 | W7: =SUM(Q7:V7) -> 8 | AA7: =SUM(X7:Z7) -> 0
A8: 0187 | B8: HARSHAD | C8: 3 | D8: 0 | E8: 0 | F8: 8 | G8: 0 | H8: 4 | I8: =SUM(C8:H8) -> 15 | M8: =SUM(J8:L8) -> 0 | O8: 0817 | P8: SILAS | T8: 3 | U8: 0 | V8: 0 | W8: =SUM(Q8:V8) -> 3 | AA8: =SUM(X8:Z8) -> 0
A9: 0809 | B9: ANDREW | F9: 5 | G9: 0 | H9: 0 | I9: =SUM(C9:H9) -> 5 | M9: =SUM(J9:L9) -> 0 | O9: 0117 | P9: YASIN | T9: 1 | U9: 0 | V9: 0 | W9: =SUM(Q9:V9) -> 1 | AA9: =SUM(X9:Z9) -> 0
A10: 0121 | B10: YASIN | F10: 1 | G10: 0 | H10: 0 | I10: =SUM(C10:H10) -> 1 | M10: =SUM(J10:L10) -> 0 | O10: 0336 | P10: SAMUEL | T10: 2 | U10: 0 | V10: 0 | W10: =SUM(Q10:V10) -> 2 | AA10: =SUM(X10:Z10) -> 0
A11: 0009 | B11: SREE | F11: 3 | G11: 1 | H11: 1 | I11: =SUM(C11:H11) -> 5 | M11: =SUM(J11:L11) -> 0 | O11: 0602 | P11: VISHWA | T11: 4 | U11: 0 | V11: 0 | W11: =SUM(Q11:V11) -> 4 | AA11: =SUM(X11:Z11) -> 0
A12: 0765 | B12: HARLEY | F12: 4 | G12: 2 | H12: 2 | I12: =SUM(C12:H12) -> 8 | M12: =SUM(J12:L12) -> 0 | O12: 0859 | P12: FARHAN | T12: 1 | U12: 0 | V12: 1 | W12: =SUM(Q12:V12) -> 2 | AA12: =SUM(X12:Z12) -> 0
A13: 0067 | B13: GIREESH | C13: 2 | D13: 0 | E13: 0 | F13: 1 | G13: 0 | H13: 0 | I13: =SUM(C13:H13) -> 3 | M13: =SUM(J13:L13) -> 0 | O13: 0925 | P13: JOHN | T13: 2 | U13: 1 | V13: 0 | W13: =SUM(Q13:V13) -> 3 | AA13: =SUM(X13:Z13) -> 0
A14: 0003 | B14: DAWOOD | F14: 4 | G14: 0 | H14: 0 | I14: =SUM(C14:H14) -> 4 | M14: =SUM(J14:L14) -> 0 | O14: 0314 | P14: YASIN | T14: 0 | U14: 0 | V14: 0 | W14: =SUM(Q14:V14) -> 0 | AA14: =SUM(X14:Z14) -> 0
A15: 0903 | B15: RAJU | F15: 2 | G15: 1 | H15: 3 | I15: =SUM(C15:H15) -> 6 | M15: =SUM(J15:L15) -> 0 | O15: 0821 | P15: CHARLES | T15: 5 | U15: 1 | V15: 1 | W15: =SUM(Q15:V15) -> 7 | AA15: =SUM(X15:Z15) -> 0
A16: 0019 | B16: BRIGHT | F16: 0 | G16: 0 | H16: 2 | I16: =SUM(C16:H16) -> 2 | M16: =SUM(J16:L16) -> 0 | O16: 0542 | P16: REJITH | T16: 1 | U16: 0 | V16: 1 | W16: =SUM(Q16:V16) -> 2 | AA16: =SUM(X16:Z16) -> 0
A17: 0193 | B17: GIREESH | F17: 4 | G17: 0 | H17: 2 | I17: =SUM(C17:H17) -> 6 | M17: =SUM(J17:L17) -> 0 | O17: 0614 | P17: VISHWA | T17: 1 | U17: 0 | V17: 1 | W17: =SUM(Q17:V17) -> 2 | AA17: =SUM(X17:Z17) -> 0
A18: 0163 | B18: NABIN | F18: 5 | G18: 0 | H18: 1 | I18: =SUM(C18:H18) -> 6 | M18: =SUM(J18:L18) -> 0 | O18: 0522 | P18: NIL | T18: 0 | U18: 0 | V18: 0 | W18: =SUM(Q18:V18) -> 0 | AA18: =SUM(X18:Z18) -> 0
A19: 0083 | B19: MANU | F19: 9 | G19: 0 | H19: 3 | I19: =SUM(C19:H19) -> 12 | M19: =SUM(J19:L19) -> 0 | O19: 0524 | P19: NOT STARTED | T19: 0 | U19: 0 | V19: 0 | W19: =SUM(Q19:V19) -> 0 | AA19: =SUM(X19:Z19) -> 0
A20: 0057 | B20: BRYAN | F20: 3 | G20: 0 | H20: 0 | I20: =SUM(C20:H20) -> 3 | M20: =SUM(J20:L20) -> 0 | O20: 0512 | P20: NOT STARTED | T20: 0 | U20: 0 | V20: 0 | W20: =SUM(Q20:V20) -> 0 | AA20: =SUM(X20:Z20) -> 0
A21: 0546 | B21: REJITH | F21: 6 | G21: 1 | H21: 4 | I21: =SUM(C21:H21) -> 11 | M21: =SUM(J21:L21) -> 0 | O21: 0568 | P21: SALMAN | T21: 0 | U21: 1 | V21: 0 | W21: =SUM(Q21:V21) -> 1 | AA21: =SUM(X21:Z21) -> 0
A22: 0143 | B22: ANURAG | F22: 4 | G22: 0 | H22: 1 | I22: =SUM(C22:H22) -> 5 | M22: =SUM(J22:L22) -> 0 | O22: 0344 | P22: GEORGE DL | T22: 0 | U22: 0 | V22: 0 | W22: =SUM(Q22:V22) -> 0 | AA22: =SUM(X22:Z22) -> 0
A23: 0857 | B23: FARHAN | F23: 1 | G23: 0 | H23: 0 | I23: =SUM(C23:H23) -> 1 | M23: =SUM(J23:L23) -> 0 | O23: 0500 | P23: WAHAB | T23: 0 | U23: 0 | V23: 0 | W23: =SUM(Q23:V23) -> 0 | AA23: =SUM(X23:Z23) -> 0
A24: 0528 | B24: REJITH | F24: 0 | G24: 0 | H24: 2 | I24: =SUM(C24:H24) -> 2 | M24: =SUM(J24:L24) -> 0 | O24: 0532 | P24: SALMAN | T24: 1 | U24: 0 | V24: 0 | W24: =SUM(Q24:V24) -> 1 | AA24: =SUM(X24:Z24) -> 0
A25: 0075 | B25: ALEXEEV | F25: 4 | G25: 1 | H25: 0 | I25: =SUM(C25:H25) -> 5 | M25: =SUM(J25:L25) -> 0 | O25: 0416 | P25: JAMIL DL | T25: 0 | U25: 0 | V25: 0 | W25: =SUM(Q25:V25) -> 0 | AA25: =SUM(X25:Z25) -> 0
... A30: 0061 | B30: BARSHAD | F30: 10 | G30: 0 | H30: 6 | I30: =SUM(C30:H30) -> 16 | M30: =SUM(J30:L30) -> 0 | O30: 0374 | P30: MYO | T30: 0 | U30: 0 | V30: 2 | W30: =SUM(Q30:V30) -> 2 | AA30: =SUM(X30:Z30) -> 0
A31: 0095 | B31: BIR | C31: 2 | D31: 0 | E31: 0 | F31: 7 | G31: 0 | H31: 1 | I31: =SUM(C31:H31) -> 10 | M31: =SUM(J31:L31) -> 0 | O31: 0538 | P31: NOT STARTED | T31: 0 | U31: 0 | V31: 0 | W31: =SUM(Q31:V31) -> 0 | AA31: =SUM(X31:Z31) -> 0
A32: 0514 | B32: REJITH | F32: 4 | G32: 0 | H32: 1 | I32: =SUM(C32:H32) -> 5 | M32: =SUM(J32:L32) -> 0 | O32: 0767 | P32: HARLEY | T32: 4 | U32: 0 | V32: 3 | W32: =SUM(Q32:V32) -> 7 | AA32: =SUM(X32:Z32) -> 0
A33: 0091 | B33: JATIN | F33: 7 | G33: 1 | H33: 2 | I33: =SUM(C33:H33) -> 10 | M33: =SUM(J33:L33) -> 0 | W33: =SUM(Q33:V33) -> 0 | AA33: =SUM(X33:Z33) -> 0
A34: 0047 | B34: JATIN | F34: 4 | G34: 0 | H34: 4 | I34: =SUM(C34:H34) -> 8 | M34: =SUM(J34:L34) -> 0 | W34: =SUM(Q34:V34) -> 0 | AA34: =SUM(X34:Z34) -> 0
A35: 0721 | B35: FELIX | C35: 2 | D35: 0 | E35: 0 | F35: 4 | G35: 0 | H35: 1 | I35: =SUM(C35:H35) -> 7 | M35: =SUM(J35:L35) -> 0 | W35: =SUM(Q35:V35) -> 0 | AA35: =SUM(X35:Z35) -> 0
A36: 0149 | B36: BIR | C36: 1 | D36: 0 | E36: 0 | F36: 3 | G36: 0 | H36: 2 | I36: =SUM(C36:H36) -> 6 | M36: =SUM(J36:L36) -> 0 | W36: =SUM(Q36:V36) -> 0 | AA36: =SUM(X36:Z36) -> 0
A37: 0125 | B37: NABIN | C37: 2 | D37: 0 | E37: 0 | F37: 5 | G37: 1 | H37: 2 | I37: =SUM(C37:H37) -> 10 | M37: =SUM(J37:L37) -> 0 | W37: =SUM(Q37:V37) -> 0 | AA37: =SUM(X37:Z37) -> 0
A38: 0953 | B38: KIMANI | F38: 6 | G38: 0 | H38: 0 | I38: =SUM(C38:H38) -> 6 | M38: =SUM(J38:L38) -> 0 | W38: =SUM(Q38:V38) -> 0 | AA38: =SUM(X38:Z38) -> 0
A39: 0508 | B39: WAHAB | F39: 6 | G39: 0 | H39: 0 | I39: =SUM(C39:H39) -> 6 | M39: =SUM(J39:L39) -> 0 | W39: =SUM(Q39:V39) -> 0 | AA39: =SUM(X39:Z39) -> 0
A40: 0803 | B40: RAJU | F40: 1 | G40: 0 | H40: 9 | I40: =SUM(C40:H40) -> 10 | M40: =SUM(J40:L40) -> 0 | W40: =SUM(Q40:V40) -> 0 | AA40: =SUM(X40:Z40) -> 0
A41: 0051 | B41: YASIN | F41: 6 | G41: 0 | H41: 1 | I41: =SUM(C41:H41) -> 7 | M41: =SUM(J41:L41) -> 0 | W41: =SUM(Q41:V41) -> 0 | AA41: =SUM(X41:Z41) -> 0
A42: 0175 | B42: SALMAN | F42: 3 | G42: 0 | H42: 1 | I42: =SUM(C42:H42) -> 4 | M42: =SUM(J42:L42) -> 0 | W42: =SUM(Q42:V42) -> 0 | AA42: =SUM(X42:Z42) -> 0
A43: 0085 | B43: JAMIL DL | F43: 4 | G43: 0 | H43: 0 | I43: =SUM(C43:H43) -> 4 | M43: =SUM(J43:L43) -> 0 | W43: =SUM(Q43:V43) -> 0 | AA43: =SUM(X43:Z43) -> 0
A44: 0839 | B44: ANDREW | F44: 0 | G44: 0 | H44: 1 | I44: =SUM(C44:H44) -> 1 | M44: =SUM(J44:L44) -> 0 | W44: =SUM(Q44:V44) -> 0 | AA44: =SUM(X44:Z44) -> 0
...

Sheet Plan vs Advance
A2: Advance planned v/s Built | F2: 1300-1600 | I2: Date | K2: 45135 | S2: Date | U2: 45986
I3: Day | K3: Wednesday | S3: Day | U3: Tuesday
A4: Planned | I4: Shift | S4: Shift | U4: 1
A5: Details | B5: PMC-AMF | C5: ALF-PLA | D5: AKE-RKE | E5: SCLR Pcs | F5: Total | I5: Duty | K5: 21:00-09:00 | S5: Duty | U5: 21:00-09:00 | AO5: Sunday
A6: Planned | B6: 215 | C6: 18 | D6: 81 | E6: 0 | F6: =B6+C6+D6 -> 314 | I6: Day Shift handover | S6: Night Shift handover | AO6: Monday
A7: Advance built | I7: Flights | K7: Handover Details | M7: Advance Planned | S7: Flights | U7: Handover Details | W7: Advance Planned | AO7: Tuesday
A8: Details | B8: PMC-AMF | C8: ALF-PLA | D8: AKE-RKE | E8: SCLR Pcs | F8: Total | I8: A/F | J8: ='BUP Shift Details Day'!P49 -> 0 | K8: Pending Advance | L8: =Q20 -> 156 | M8: First Wave (06:00-09:00) | O8: Second Wave (09:01-12:59) | Q8: Total | S8: E/M | T8: ='BUP Shift Details Night'!P49 -> 67 | U8: Pending Advance | V8: =AA20 -> 156 | W8: First Wave (13:00-16:00) | Y8: Second Wave (16:01-23:59) | AA8: Total | AO8: Wednesday
A9: Built | B9: ='Adv Report'!E80 -> 154 | C9: ='Adv Report'!F80 -> 12 | D9: ='Adv Report'!G80 -> 60 | F9: =B9+C9+D9 -> 226 | I9: E/M | J9: ='BUP Shift Details Day'!P50 -> 0 | K9: Pending ULDs till 03:00 | L9: ='BUP Shift Details Day'!P172 -> 0 | M9: ='BUP Shift Details Day'!P160 -> 314 | O9: ='BUP Shift Details Day'!P161 -> 145 | Q9: =SUM(M9:P9) -> 459 | S9: L/M | T9: ='BUP Shift Details Night'!P50 -> 100 | U9: Pending ULDs till 16:00 | V9: ='BUP Shift Details Night'!P172 -> 74 | W9: ='BUP Shift Details Night'!P160 -> 314 | Y9: ='BUP Shift Details Night'!P161 -> 145 | AA9: ='BUP Shift Details Night'!P162 -> 459 | AO9: Thursday
A10: Thru | B10: ='Adv Report'!E81 -> 14 | C10: ='Adv Report'!F81 -> 0 | D10: ='Adv Report'!G81 -> 0 | F10: =B10+C10+D10 -> 14 | I10: L/M | J10: ='BUP Shift Details Day'!P51 -> 0 | K10: Pending ULDs from 03:00-06:00 | L10: ='BUP Shift Details Day'!P173 -> 0 | M10: Advance Range & Target | S10: A/F | T10: ='BUP Shift Details Night'!P51 -> 70 | U10: Pending ULDs from 16:00-23:59 | V10: ='BUP Shift Details Night'!P173 -> 82 | W10: Advance Range & Target | AO10: Friday
A11: TOTAL | B11: =B9+B10 -> 168 | C11: =C9+C10 -> 12 | D11: =D9+D10 -> 60 | E11: =E9+E10 -> 0 | F11: =B11+C11+D11 -> 240 | I11: TRK | J11: ='BUP Shift Details Day'!P52 -> 0 | K11: Pending Total | L11: =SUM(L8:L10) -> 156 | M11: First Wave Planned | N11: First Wave | O11: Second | P11: Total Planned | Q11: Total | S11: TRK | T11: ='BUP Shift Details Night'!P52 -> 6 | U11: Pending Total | V11: =SUM(V8:V10) -> 312 | W11: First Wave Planned | X11: First Wave | Y11: Second | Z11: Total Planned | AA11: Total | AO11: Saturday
A12: Pending | I12: Total | J12: ='BUP Shift Details Day'!P53 -> 0 | M12: Less than 150 | N12: =M9*60% -> 188.4 | O12: =Q12-N12 -> -4.8 | P12: less than 350 or upto 400 | Q12: =Q9*40% -> 183.6 | S12: Total | T12: ='BUP Shift Details Night'!P53 -> 243 | W12: Less than 150 | X12: =W9*60% -> 188.4 | Y12: =AA12-X12 -> -4.8 | Z12: less than 350 or upto 400 | AA12: =AA9*40% -> 183.6
A13: ULD Details | B13: PMC-AMF | C13: ALF-PLA | D13: AKE-RKE | E13: SCLR Pcs | F13: Total | I13: Man Power | K13: Efficiency Target | M13: 150 to 200 | N13: =M9*65% -> 204.1 | O13: =Q13-N13 -> 2.45 | P13: 400 to 450 | Q13: =Q9*45% -> 206.55 | S13: Man Power | U13: Efficiency Target | W13: 150 to 200 | X13: =W9*65% -> 204.1 | Y13: =AA13-X13 -> 2.45 | Z13: 400 to 450 | AA13: =AA9*45% -> 206.55 | AO13: 1
A14: To action | B14: =B6-B11 -> 47 | C14: =C6-C11 -> 6 | D14: =D6-D11 -> 21 | E14: =E6-E11 -> 0 | F14: =F6-F11 -> 74 | I14: Staffs (POS+Floor +OS Staffs) | J14: ='BUP Shift Details Day'!P26+'BUP Shift Details Day'!P27+'BUP Shift Details Day'!P28+'BUP Shift Details Day'!P29+'BUP Shift Details Day'!P31 -> 0 | K14: Average Efficiency | L14: 1.9 | M14: 200 to 250 | N14: =M9*70% -> 219.8 | O14: =Q14-N14 -> 9.7 | P14: 450 to 500 or greater | Q14: =Q9*50% -> 229.5 | S14: Staffs (POS+Floor +OS Staffs) | T14: ='BUP Shift Details Night'!P26+'BUP Shift Details Night'!P27+'BUP Shift Details Night'!P28+'BUP Shift Details Night'!P29+'BUP Shift Details Night'!P31 -> 42 | U14: Average Efficiency | V14: 1.9 | W14: 200 to 250 | X14: =W9*70% -> 219.8 | Y14: =AA14-X14 -> 9.7 | Z14: 450 to 500 or greater | AA14: =AA9*50% -> 229.5 | AO14: 2
A15: Advance planned v/s Built | F15: 1601-2359 | I15: Overtime | J15: ='BUP Shift Details Day'!P30 -> 0 | K15: Per Staff Efficiency | L15: =L14*12 -> 22.8 | M15: Advance Built | S15: Overtime | T15: ='BUP Shift Details Night'!P30 -> 3 | U15: Per Staff Efficiency | V15: =V14*12 -> 22.8 | W15: Advance Built | AO15: 3
I16: Total | J16: ='BUP Shift Details Day'!P32 -> 0 | K16: Staffs Required | L16: =L21/L15 -> 13.289474 | M16: First Wave | O16: Second Wave | Q16: Total | S16: Total | T16: ='BUP Shift Details Night'!P32 -> 45 | U16: Staffs Required | V16: =V21/V15 -> 39.078947 | W16: First Wave | Y16: Second Wave | AA16: Total | AO16: 4
A17: Planned | I17: Shift Efficiency | K17: Adv Target (210 to 250) | M17: ='BUP Shift Details Day'!P164 -> 240 | O17: ='BUP Shift Details Day'!P165 -> 63 | Q17: =SUM(M17:P17) -> 303 | S17: Shift Efficiency | U17: Adv Target (190 to 230) | W17: ='BUP Shift Details Night'!P164 -> 240 | Y17: ='BUP Shift Details Night'!P165 -> 63 | AA17: ='BUP Shift Details Night'!P166 -> 303
A18: Details | B18: PMC-AMF | C18: ALF-PLA | D18: AKE-RKE | E18: SCLR Pcs | F18: Total | I18: Total ULD | J18: ='BUP Shift Details Day'!P41 -> 303 | K18: AFT Built | L18: =Q22+Q28 -> 0 | M18: Advance Pending | S18: Total ULD | T18: ='BUP Shift Details Night'!P41 -> 891 | U18: E/M Built | V18: =AA22 -> 78 | W18: Advance Pending | AO18: 09:00-21:00
A19: Planned | B19: 95 | C19: 11 | D19: 39 | F19: =B19+C19+D19 -> 145 | I19: Total Hours | J19: ='BUP Shift Details Day'!P42 -> 0 | K19: E/M Built | L19: =Q23 -> 0 | M19: First Wave | O19: Second | Q19: Total | S19: Total Hours | T19: ='BUP Shift Details Night'!P42 -> 506 | U19: L/M Built | V19: =AA23+AA28 -> 510 | W19: First Wave | Y19: Second Wave | AA19: Total | AO19: 21:00-09:00
A20: Advance built | I20: Efficiency | J20: ='BUP Shift Details Day'!P43 -> #DIV/0! | K20: Advance | L20: =Q24 -> 303 | M20: =M9-M17 -> 74 | O20: =O9-O17 -> 82 | Q20: =Q9-Q17 -> 156 | S20: Efficiency | T20: ='BUP Shift Details Night'!P43 -> 1.7608696 | U20: Advance | V20: =AA24 -> 303 | W20: =W9-W17 -> 74 | Y20: =Y9-Y17 -> 82 | AA20: =AA9-AA17 -> 156
A21: Details | B21: PMC-AMF | C21: ALF-PLA | D21: AKE-RKE | E21: SCLR Pcs | F21: Total | I21: Screening Load | K21: Total | L21: =SUM(L18:L20) -> 303 | M21: Supervisor | P21: Sanity | S21: Screening Load | U21: Total | V21: =SUM(V18:V20) -> 891 | W21: Supervisor | Z21: Sanity
A22: Built | B22: ='Adv Report'!S80 -> 34 | C22: ='Adv Report'!T80 -> 3 | D22: ='Adv Report'!U80 -> 24 | F22: =B22+C22+D22 -> 61 | I22: Planned Pcs | J22: ='BUP Shift Details Day'!P180 -> 0 | M22: ='BUP Shift Details Day'!A5 -> 0 | P22: AFT Pending | Q22: ='BUP Shift Details Day'!P184 -> 0 | S22: Planned Pcs | T22: ='BUP Shift Details Night'!P180 -> 1273 | W22: ='BUP Shift Details Night'!A5 -> NADEEM | Z22: E/M Pending | AA22: ='BUP Shift Details Night'!P184 -> 78
A23: Thru | B23: ='Adv Report'!S81 -> 2 | C23: ='Adv Report'!T81 -> 0 | D23: ='Adv Report'!U81 -> 0 | F23: =B23+C23+D23 -> 2 | I23: Built Pcs | J23: ='BUP Shift Details Day'!P181 -> 0 | K23: Night Shift Work Load | P23: E/M Built | Q23: ='BUP Shift Details Day'!P185 -> 0 | S23: Built Pcs | T23: ='BUP Shift Details Night'!P181 -> 1273 | U23: Day Shift Work Load | Z23: L/M Pending | AA23: ='BUP Shift Details Night'!P185 -> 306
A24: TOTAL | B24: =B22+B23 -> 36 | C24: =C22+C23 -> 3 | D24: =D22+D23 -> 24 | E24: =E22+E23 -> 0 | F24: =B24+C24+D24 -> 63 | I24: Pending Pcs | J24: ='BUP Shift Details Day'!P182 -> 0 | K24: Flights | M24: Pending ULDs | P24: Advance | Q24: ='BUP Shift Details Day'!P186 -> 303 | S24: Pending Pcs | T24: ='BUP Shift Details Night'!P182 -> 0 | U24: Flights | W24: Pending ULDs | Z24: Advance | AA24: ='BUP Shift Details Night'!P186 -> 303
A25: Pending | I25: Peak Load Analysis | K25: E/M | L25: ='BUP Shift Details Day'!P54 -> 0 | M25: E/M Pending | N25: =SUM(L9:L10) -> 0 | P25: Super Advance | Q25: ='BUP Shift Details Day'!P187 -> 0 | S25: Peak Load Analysis | U25: A/F | V25: ='BUP Shift Details Night'!P54 -> 0 | W25: A/F Pending | X25: =V11 -> 312 | Z25: Super Advance | AA25: ='BUP Shift Details Night'!P187 -> 0
A26: ULD Details | B26: PMC-AMF | C26: ALF-PLA | D26: AKE-RKE | E26: SCLR Pcs | F26: Total | I26: Afternoon | J26: =SUM('BUP Shift Details Day'!F10:F109) -> 0 | K26: L/M | L26: ='BUP Shift Details Day'!P55 -> 0 | M26: L/M Pending | N26: =L8 -> 156 | P26: Total | Q26: ='BUP Shift Details Day'!P188 -> 303 | S26: Early Morning | T26: =SUM('BUP Shift Details Night'!F10:F109) -> 115 | U26: E/M | V26: ='BUP Shift Details Night'!P55 -> 70 | W26: E/M Average | X26: 200 | Z26: Total | AA26: ='BUP Shift Details Night'!P188 -> 687
A27: To action | B27: =B19-B24 -> 59 | C27: =C19-C24 -> 8 | D27: =D19-D24 -> 15 | E27: =E19-E24 -> 0 | F27: =F19-F24 -> 82 | I27: Early Morning | J27: =SUM('Early Morning Report'!K52,'Early Morning Report'!K105) -> 0 | K27: A/F | L27: ='BUP Shift Details Day'!P56 -> 0 | M27: Advance Target | N27: 210 | P27: Report Total | Q27: ='BUP Shift Details Day'!P189 -> 303 | S27: Late Morning | T27: =SUM('BUP Shift Details Night'!F111:F260) -> 473 | U27: L/M | V27: ='BUP Shift Details Night'!P56 -> 0 | W27: Advance Target | X27: 230 | Z27: Report Total | AA27: ='BUP Shift Details Night'!P189 -> 891
A28: Total Advance | I28: Late Morning | J28: ='Adv Report'!O84 -> 303 | K28: TRK | L28: ='BUP Shift Details Day'!P57 -> 0 | M28: Total | N28: =SUM(N25:N27) -> 366 | P28: Var/Adnl | Q28: ='BUP Shift Details Day'!P190 -> 0 | S28: Afternoon | T28: ='Adv Report'!O84 -> 303 | U28: TRK | V28: ='BUP Shift Details Night'!P57 -> 0 | W28: Total | X28: =SUM(X25:Y27) -> 742 | Z28: Var/Adnl | AA28: ='BUP Shift Details Night'!P190 -> 204
A29: Details | B29: PMC-AMF | C29: ALF-PLA | D29: AKE-RKE | E29: SCLR Pcs | F29: Total | I29: Total | J29: =SUM(J26:J28) -> 303 | K29: Total | L29: ='BUP Shift Details Day'!P58 -> 0 | M29: Average Efficiency | N29: 1.55 | P29: Var/Adnl % | Q29: ='BUP Shift Details Day'!P191 -> 0 | S29: Total | T29: =SUM(T26:T28) -> 891 | U29: Total | V29: ='BUP Shift Details Night'!P58 -> 1 | W29: Average Efficiency | X29: 1.75 | Z29: Var/Adnl % | AA29: ='BUP Shift Details Night'!P191 -> 0.29694323
A30: =F2 -> 1300-1600 | B30: =B11 -> 168 | C30: =C11 -> 12 | D30: =D11 -> 60 | E30: =E11 -> 0 | F30: =B30+C30+D30 -> 240 | K30: Per Staff Efficiency | L30: =N29*12 -> 18.6 | M30: Staff requirement | N30: =N28/L30 -> 19.677419 | P30: Reused Plastic | Q30: ='BUP Shift Details Day'!P90 -> 1 | U30: Per Staff Efficiency | V30: =X29*12 -> 21 | W30: Staff requirement | X30: =X28/V30 -> 35.333333 | Z30: Reused Plastic | AA30: ='BUP Shift Details Night'!P90 -> 0.83
A31: =F15 -> 1601-2359 | B31: =B24 -> 36 | C31: =C24 -> 3 | D31: =D24 -> 24 | E31: =E24 -> 0 | F31: =B31+C31+D31 -> 63 | I31: Next Shift Planning | S31: Next Shift Planning
A32: TOTAL | B32: =SUM(B30:B31) -> 204 | C32: =SUM(C30:C31) -> 15 | D32: =SUM(D30:D31) -> 84 | E32: =SUM(E30:E31) -> 0 | F32: =B32+C32+D32 -> 303 | I32: Next Day Shift | N32: Next Night Shift | S32: Next Night Shift | X32: Next Day Shift
A33: Total Pending | I33: Average A/F | J33: =GETPIVOTDATA("Average of Peak A/F",' Day Averages'!$A$4,"Duty Hrs","DX") -> 145.19231 | K33: Average Efficiency | L33: 1.75 | N33: Average E/M | O33: =GETPIVOTDATA("Average of Peak E/M",'Night Averages'!$A$3,"Duty Hrs2","NI") -> 45.653846 | P33: Average Efficiency | Q33: 1.55 | S33: Average E/M | T33: =GETPIVOTDATA("Average of Peak E/M",'Night Averages'!$A$3,"Duty Hrs2","NI") -> 45.653846 | U33: Average Efficiency | V33: 1.55 | X33: Average A/F | Y33: =GETPIVOTDATA("Average of Peak A/F",' Day Averages'!$A$4,"Duty Hrs","DX") -> 145.19231 | Z33: Average Efficiency | AA33: 1.75
A34: Details | B34: PMC-AMF | C34: ALF-PLA | D34: AKE-RKE | E34: SCLR Pcs | F34: Total | I34: Average E/M | J34: =GETPIVOTDATA("Average of Early Morning Total",' Day Averages'!$A$4,"Duty Hrs","DX") -> 180.5 | K34: Per Staff Efficiency | L34: =L33*12 -> 21 | N34: Average L/M | O34: =GETPIVOTDATA("Average of Late Morning",'Night Averages'!$A$3,"Duty Hrs2","NI") -> 276.30769 | P34: Per Staff Efficiency | Q34: =Q33*12 -> 18.6 | S34: Average L/M | T34: =GETPIVOTDATA("Average of Late Morning",'Night Averages'!$A$3,"Duty Hrs2","NI") -> 276.30769 | U34: Per Staff Efficiency | V34: =V33*12 -> 18.6 | X34: Average E/M | Y34: =GETPIVOTDATA("Average of Early Morning Total",' Day Averages'!$A$4,"Duty Hrs","DX") -> 180.5 | Z34: Per Staff Efficiency | AA34: =AA33*12 -> 21
A35: =F2 -> 1300-1600 | B35: =B14 -> 47 | C35: =C14 -> 6 | D35: =D14 -> 21 | E35: =E14 -> 0 | F35: =B35+C35+D35 -> 74 | I35: Average Advance | J35: =GETPIVOTDATA("Average of Total Advance",' Day Averages'!$A$4,"Duty Hrs","DX") -> 195.03846 | K35: Staffs Required | L35: =J36/L34 -> 24.796703 | N35: Average Advance | O35: =GETPIVOTDATA("Average of Total Advance2",'Night Averages'!$A$3,"Duty Hrs2","NI") -> 191.80769 | P35: Staffs Required | Q35: =O36/Q34 -> 27.622002 | S35: Average Advance | T35: =GETPIVOTDATA("Average of Total Advance2",'Night Averages'!$A$3,"Duty Hrs2","NI") -> 191.80769 | U35: Staffs Required | V35: =T36/V34 -> 27.622002 | X35: Average Advance | Y35: =GETPIVOTDATA("Average of Total Advance",' Day Averages'!$A$4,"Duty Hrs","DX") -> 195.03846 | Z35: Staffs Required | AA35: =Y36/AA34 -> 24.796703
A36: =F15 -> 1601-2359 | B36: =B27 -> 59 | C36: =C27 -> 8 | D36: =D27 -> 15 | E36: =E27 -> 0 | F36: =B36+C36+D36 -> 82 | I36: Total | J36: =SUM(J33:J35) -> 520.73077 | N36: Total | O36: =SUM(O33:O35) -> 513.76923 | S36: Total | T36: =SUM(T33:T35) -> 513.76923 | X36: Total | Y36: =SUM(Y33:Y35) -> 520.73077
A37: TOTAL | B37: =B35+B36 -> 106 | C37: =C35+C36 -> 14 | D37: =D35+D36 -> 36 | E37: =E35+E36 -> 0 | F37: =B37+C37+D37 -> 156

Sheet Plan vs Advance Old
A1: Advance planned v/s Built | F1: 1300-1600 | I1: Date | K1: 45204 | N1: Date | P1: 45204
I2: Day | N2: Day
A3: Planned | I3: Shift | N3: Shift
A4: Details | B4: PMC-AMF | C4: ALF-PLA | D4: AKE-RKE | E4: SCLR Pcs | F4: Total | I4: Duty | K4: 09:00-21:00 | N4: Duty | P4: 21:00-09:00 | AF4: Sunday
A5: Planned | F5: =B5+C5+D5 -> 0 | I5: Flights | K5: Total Advance | N5: Flights | P5: Total Advance | AF5: Monday
A6: Advance built | I6: E/M | J6: ='BUP Shift Details Day'!P54 -> 0 | K6: Pending Advance | L6: =J22 -> 156 | N6: A/F | O6: ='BUP Shift Details Night'!P54 -> 0 | P6: Built ULDs | Q6: ='BUP Shift Details Night'!P166 -> 303 | AF6: Tuesday
A7: Details | B7: PMC-AMF | C7: ALF-PLA | D7: AKE-RKE | E7: SCLR Pcs | F7: Total | I7: L/M | J7: ='BUP Shift Details Day'!P55 -> 0 | K7: Pending ULDs till 03:00 | L7: ='BUP Shift Details Day'!P172 -> 0 | N7: E/M | O7: ='BUP Shift Details Night'!P55 -> 70 | P7: Pending ULDs till 03:00 | AF7: Wednesday
A8: Built | B8: ='Adv Report'!E80 -> 154 | C8: ='Adv Report'!F80 -> 12 | D8: ='Adv Report'!G80 -> 60 | F8: =B8+C8+D8 -> 226 | I8: A/F | J8: ='BUP Shift Details Day'!P56 -> 0 | K8: Pending ULDs from 03:00-06:00 | L8: ='BUP Shift Details Day'!P173 -> 0 | N8: L/M | O8: ='BUP Shift Details Night'!P56 -> 0 | P8: Pending ULDs from 03:00-06:00 | AF8: Thursday
A9: Thru | B9: ='Adv Report'!E81 -> 14 | C9: ='Adv Report'!F81 -> 0 | D9: ='Adv Report'!G81 -> 0 | F9: =B9+C9+D9 -> 14 | I9: TRK | J9: ='BUP Shift Details Day'!P57 -> 0 | K9: Pending ULDs till 16:00 | N9: TRK | O9: ='BUP Shift Details Night'!P57 -> 0 | P9: Pending ULDs till 16:00 | Q9: ='BUP Shift Details Night'!P172 -> 74 | AF9: Friday
A10: TOTAL | B10: =B8+B9 -> 168 | C10: =C8+C9 -> 12 | D10: =D8+D9 -> 60 | E10: =E8+E9 -> 0 | F10: =B10+C10+D10 -> 240 | I10: Total | J10: ='BUP Shift Details Day'!P58 -> 0 | K10: Pending ULDs from 16:00-23:59 | N10: Total | O10: ='BUP Shift Details Night'!P58 -> 1 | P10: Pending ULDs from 16:00-23:59 | Q10: ='BUP Shift Details Night'!P173 -> 82 | AF10: Saturday
A11: Pending | I11: Advance Planned | K11: Pending Total | L11: =SUM(L6:L8) -> 156 | N11: Advance Planned | P11: Pending Total | Q11: =SUM(Q9:Q10) -> 156
A12: ULD Details | B12: PMC-AMF | C12: ALF-PLA | D12: AKE-RKE | E12: SCLR Pcs | F12: Total | I12: First Wave | J12: ='BUP Shift Details Day'!P160 -> 314 | K12: Staffs | N12: First Wave | O12: ='BUP Shift Details Night'!P160 -> 314 | P12: Staffs | AF12: 1
A13: To action | B13: =B5-B10 -> -168 | C13: =C5-C10 -> -12 | D13: =D5-D10 -> -60 | E13: =E5-E10 -> 0 | F13: =F5-F10 -> -240 | I13: Second | J13: ='BUP Shift Details Day'!P161 -> 145 | K13: Positonal | L13: ='BUP Shift Details Day'!P26 -> 0 | N13: Second | O13: ='BUP Shift Details Night'!P161 -> 145 | P13: Positonal | Q13: ='BUP Shift Details Night'!P26 -> 6 | AF13: 2
A14: Advance planned v/s Built | F14: 1601-2359 | I14: Total | J14: =SUM(J12:J13) -> 459 | K14: Floor | L14: ='BUP Shift Details Day'!P27+'BUP Shift Details Day'!P28+'BUP Shift Details Day'!P29+'BUP Shift Details Day'!P30 -> 0 | N14: Total | O14: =SUM(O12:O13) -> 459 | P14: Floor | Q14: ='BUP Shift Details Night'!P27+'BUP Shift Details Night'!P28+'BUP Shift Details Night'!P29+'BUP Shift Details Night'!P30 -> 38 | AF14: 3
I15: Advance Built | K15: Total | L15: ='BUP Shift Details Day'!P31 -> 0 | N15: Advance Built | P15: Total | Q15: ='BUP Shift Details Night'!P31 -> 1 | AF15: 4
A16: Planned | I16: First Wave | J16: ='BUP Shift Details Day'!P164 -> 240 | K16: Screening Load | N16: First Wave | O16: ='BUP Shift Details Night'!P164 -> 240 | P16: Screening Load
A17: Details | B17: PMC-AMF | C17: ALF-PLA | D17: AKE-RKE | E17: SCLR Pcs | F17: Total | I17: Second | J17: ='BUP Shift Details Day'!P165 -> 63 | K17: Planned Pcs | L17: ='BUP Shift Details Day'!P180 -> 0 | N17: Second | O17: ='BUP Shift Details Night'!P165 -> 63 | P17: Planned Pcs | Q17: ='BUP Shift Details Night'!P180 -> 1273 | AF17: 09:00-21:00
A18: Planned | F18: =B18+C18+D18 -> 0 | I18: Total | J18: =SUM(J16:J17) -> 303 | K18: Built Pcs | L18: =L17-L19 -> 0 | N18: Total | O18: =SUM(O16:O17) -> 303 | P18: Built Pcs | Q18: =Q17-Q19 -> 1273 | AF18: 21:00-09:00
A19: Advance built | I19: Advance Pending | K19: Pending Pcs | L19: ='BUP Shift Details Day'!P182 -> 0 | N19: Advance Pending | P19: Pending Pcs | Q19: ='BUP Shift Details Night'!P182 -> 0
A20: Details | B20: PMC-AMF | C20: ALF-PLA | D20: AKE-RKE | E20: SCLR Pcs | F20: Total | I20: First Wave | J20: =J12-J16 -> 74 | K20: Sanity | N20: First Wave | O20: =O12-O16 -> 74 | P20: Sanity
A21: Built | B21: ='Adv Report'!S80 -> 34 | C21: ='Adv Report'!T80 -> 3 | D21: ='Adv Report'!U80 -> 24 | F21: =B21+C21+D21 -> 61 | I21: Second | J21: =J13-J17 -> 82 | K21: AFT Pending | L21: ='BUP Shift Details Day'!P184 -> 0 | N21: Second | O21: =O13-O17 -> 82 | P21: E/M Pending | Q21: ='BUP Shift Details Night'!P184 -> 78
A22: Thru | B22: ='Adv Report'!S81 -> 2 | C22: ='Adv Report'!T81 -> 0 | D22: ='Adv Report'!U81 -> 0 | F22: =B22+C22+D22 -> 2 | I22: Total | J22: =J14-J18 -> 156 | K22: E/M Built | L22: ='BUP Shift Details Day'!P185 -> 0 | N22: Total | O22: =O14-O18 -> 156 | P22: L/M Pending | Q22: ='BUP Shift Details Night'!P185 -> 306
A23: TOTAL | B23: =B21+B22 -> 36 | C23: =C21+C22 -> 3 | D23: =D21+D22 -> 24 | E23: =E21+E22 -> 0 | F23: =B23+C23+D23 -> 63 | I23: Shift Efficiency | K23: Advance | L23: ='BUP Shift Details Day'!P186 -> 303 | N23: Shift Efficiency | P23: Advance | Q23: ='BUP Shift Details Night'!P186 -> 303
A24: Pending | I24: Total ULD | J24: ='BUP Shift Details Day'!P40 -> 0 | K24: Super Advance | L24: ='BUP Shift Details Day'!P187 -> 0 | N24: Total ULD | O24: ='BUP Shift Details Night'!P40 -> 0 | P24: Super Advance | Q24: ='BUP Shift Details Night'!P187 -> 0
A25: ULD Details | B25: PMC-AMF | C25: ALF-PLA | D25: AKE-RKE | E25: SCLR Pcs | F25: Total | I25: Total Hours | J25: ='BUP Shift Details Day'!P41 -> 303 | K25: Total | L25: ='BUP Shift Details Day'!P188 -> 303 | N25: Total Hours | O25: ='BUP Shift Details Night'!P41 -> 891 | P25: Total | Q25: ='BUP Shift Details Night'!P188 -> 687
A26: To action | B26: =B18-B23 -> -36 | C26: =C18-C23 -> -3 | D26: =D18-D23 -> -24 | E26: =E18-E23 -> 0 | F26: =F18-F23 -> -63 | I26: Efficiency | J26: ='BUP Shift Details Day'!P42 -> 0 | K26: Report Total | L26: ='BUP Shift Details Day'!P189 -> 303 | N26: Efficiency | O26: ='BUP Shift Details Night'!P42 -> 506 | P26: Report Total | Q26: ='BUP Shift Details Night'!P189 -> 891
A27: Total Advance | I27: Advance Target (210 to 250) | K27: Var/Adnl | L27: ='BUP Shift Details Day'!P190 -> 0 | N27: Advance Target (190 to 230) | P27: Var/Adnl | Q27: ='BUP Shift Details Night'!P190 -> 204
A28: Details | B28: PMC-AMF | C28: ALF-PLA | D28: AKE-RKE | E28: SCLR Pcs | F28: Total | I28: AFT Built | J28: =L21+L27 -> 0 | K28: Var/Adnl % | L28: ='BUP Shift Details Day'!P191 -> 0 | N28: E/M Built | O28: =Q21 -> 78 | P28: Var/Adnl % | Q28: ='BUP Shift Details Night'!P191 -> 0.29694323
A29: =F1 -> 1300-1600 | B29: =B10 -> 168 | C29: =C10 -> 12 | D29: =D10 -> 60 | E29: =E10 -> 0 | F29: =B29+C29+D29 -> 240 | I29: E/M Built | J29: =L22 -> 0 | K29: Efficiency Target | N29: L/M Built | O29: =Q22+Q27 -> 510 | P29: Efficiency Target
A30: =F14 -> 1601-2359 | B30: =B23 -> 36 | C30: =C23 -> 3 | D30: =D23 -> 24 | E30: =E23 -> 0 | F30: =B30+C30+D30 -> 63 | I30: Advance | J30: =L23 -> 303 | K30: Average Efficiency | L30: 1.75 | N30: Advance | O30: =Q23 -> 303 | P30: Average Efficiency | Q30: 1.55
A31: TOTAL | B31: =SUM(B29:B30) -> 204 | C31: =SUM(C29:C30) -> 15 | D31: =SUM(D29:D30) -> 84 | E31: =SUM(E29:E30) -> 0 | F31: =B31+C31+D31 -> 303 | I31: Total | J31: =SUM(J28:J30) -> 303 | K31: Per Staff Efficiency | L31: =L30*12 -> 21 | N31: Total | O31: =SUM(O28:O30) -> 891 | P31: Per Staff Efficiency | Q31: =Q30*12 -> 18.6
A32: Total Pending | K32: Staffs Required | L32: =J31/L31 -> 14.428571 | P32: Staffs Required | Q32: =O31/Q31 -> 47.903226
A33: Details | B33: PMC-AMF | C33: ALF-PLA | D33: AKE-RKE | E33: SCLR Pcs | F33: Total
A34: =F1 -> 1300-1600 | B34: =B13 -> -168 | C34: =C13 -> -12 | D34: =D13 -> -60 | E34: =E13 -> 0 | F34: =B34+C34+D34 -> -240
A35: =F14 -> 1601-2359 | B35: =B26 -> -36 | C35: =C26 -> -3 | D35: =D26 -> -24 | E35: =E26 -> 0 | F35: =B35+C35+D35 -> -63
A36: TOTAL | B36: =B34+B35 -> -204 | C36: =C34+C35 -> -15 | D36: =D34+D35 -> -84 | E36: =E34+E35 -> 0 | F36: =B36+C36+D36 -> -303

Sheet  Day Averages
A2: Day | B2: Fri
B4: Values
A5: Duty Hrs | B5: Average of Peak A/F | C5: Average of Early Morning Total | D5: Average of Total Advance
A6: DX | B6: 145.19231 | C6: 180.5 | D6: 195.03846
A7: Grand Total | B7: 145.19231 | C7: 180.5 | D7: 195.03846

Sheet Night Averages
A1: Day2 | B1: Sun
A3: Row Labels | B3: Average of Peak E/M | C3: Average of Late Morning | D3: Average of Total Advance2
A4: NI | B4: 45.653846 | C4: 276.30769 | D4: 191.80769
A5: Grand Total | B5: 45.653846 | C5: 276.30769 | D5: 191.80769

Sheet BUP Data 
A1: Date | B1: Day | C1: Shift | D1: Duty Hrs | E1: Peak A/F | F1: Early Morning First Wave | G1: Early Morning Second Wave | H1: Early Morning Total | I1: Advance First Wave | J1: Advance Second Wave | K1: Total Advance | L1: Total DX BUP | M1: Planned PMC | N1: Planned ALF | O1: Planned AKE | P1: Total Planned F/W | Q1: Planned PMC | R1: Planned ALF | S1: Planned AKE | T1: Total Palnned S/W | U1: Build PMC | V1: Build ALF | W1: Build AKE | X1: Total Build | Y1: Pending PMC | Z1: Pending ALF | AA1: Pending AKE | AB1: Total Pending | AC1: Date | AD1: Day | AE1: Shift | AF1: Duty Hrs | AG1: Peak E/M | AH1: Late Morning | AI1: Advance First Wave | AJ1: Advance Second Wave | AK1: Total Advance | AL1: Total NI BUP | AM1: Planned PMC | AN1: Planned ALF | AO1: Planned AKE | AP1: Total Planned F/W | AQ1: Planned PMC | AR1: Planned ALF | AS1: Planned AKE | AT1: Total Palnned S/W | AU1: Build PMC | AV1: Build ALF | AW1: Build AKE | AX1: Total Build | AY1: Pending PMC | AZ1: Pending ALF | BA1: Pending AKE | BB1: Total Pending
A2: 44927 | B2: Sun | C2: 1 | D2: DX | E2: 126 | F2: 81 | G2: 118 | H2: 199 | I2: 126 | J2: 36 | K2: 162 | L2: 487 | M2: 147 | N2: 19 | O2: 51 | P2: 217 | Q2: 80 | R2: 12 | S2: 46 | T2: 138 | U2: 90 | V2: 13 | W2: 59 | X2: 162 | Y2: 137 | Z2: 18 | AA2: 38 | AB2: 193 | AC2: 44927 | AD2: Sun | AE2: 2 | AF2: NI | AG2: 48 | AH2: 259 | AI2: 101 | AJ2: 48 | AK2: 149 | AL2: 456 | AM2: 84 | AN2: 9 | AO2: 32 | AP2: 125 | AQ2: 48 | AR2: 4 | AS2: 24 | AT2: 76 | AU2: 101 | AV2: 13 | AW2: 35 | AX2: 149 | AY2: 31 | AZ2: 0 | BA2: 21 | BB2: 52
A3: 44928 | B3: Mon | C3: 3 | D3: DX | E3: 72 | F3: 71 | G3: 74 | H3: 145 | I3: 83 | J3: 66 | K3: 149 | L3: 366 | M3: 79 | N3: 13 | O3: 56 | P3: 148 | Q3: 85 | R3: 18 | S3: 58 | T3: 161 | U3: 68 | V3: 15 | W3: 66 | X3: 149 | Y3: 96 | Z3: 16 | AA3: 48 | AB3: 160 | AC3: 44928 | AD3: Mon | AE3: 4 | AF3: NI | AG3: 20 | AH3: 185 | AI3: 69 | AJ3: 56 | AK3: 125 | AL3: 330 | AM3: 68 | AN3: 5 | AO3: 36 | AP3: 109 | AQ3: 43 | AR3: 5 | AS3: 22 | AT3: 70 | AU3: 72 | AV3: 9 | AW3: 44 | AX3: 125 | AY3: 39 | AZ3: 1 | BA3: 14 | BB3: 54
A4: 44929 | B4: Tue | C4: 3 | D4: DX | E4: 58 | F4: 57 | G4: 59 | H4: 116 | I4: 82 | J4: 53 | K4: 135 | L4: 309 | M4: 91 | N4: 21 | O4: 55 | P4: 167 | Q4: 72 | R4: 14 | S4: 40 | T4: 126 | U4: 66 | V4: 15 | W4: 54 | X4: 135 | Y4: 97 | Z4: 20 | AA4: 41 | AB4: 158 | AC4: 44929 | AD4: Tue | AE4: 4 | AF4: NI | AG4: 38 | AH4: 194 | AI4: 95 | AJ4: 69 | AK4: 164 | AL4: 396 | AM4: 91 | AN4: 21 | AO4: 55 | AP4: 167 | AQ4: 72 | AR4: 14 | AS4: 40 | AT4: 126 | AU4: 66 | AV4: 15 | AW4: 54 | AX4: 135 | AY4: 97 | AZ4: 20 | BA4: 41 | BB4: 158
A5: 44930 | B5: Wed | C5: 2 | D5: DX | E5: 74 | F5: 69 | G5: 66 | H5: 135 | I5: 94 | J5: 63 | K5: 157 | L5: 366 | M5: 84 | N5: 6 | O5: 70 | P5: 160 | Q5: 69 | R5: 10 | S5: 63 | T5: 142 | U5: 83 | V5: 13 | W5: 61 | X5: 157 | Y5: 70 | Z5: 3 | AA5: 72 | AB5: 145 | AC5: 44930 | AD5: Wed | AE5: 1 | AF5: NI | AG5: 40 | AH5: 163 | AI5: 89 | AJ5: 71 | AK5: 160 | AL5: 363 | AM5: 75 | AN5: 9 | AO5: 35 | AP5: 119 | AQ5: 66 | AR5: 7 | AS5: 34 | AT5: 107 | AU5: 99 | AV5: 15 | AW5: 46 | AX5: 160 | AY5: 42 | AZ5: 1 | BA5: 23 | BB5: 66
A6: 44931 | B6: Thu | C6: 2 | D6: DX | E6: 87 | F6: 76 | G6: 66 | H6: 142 | I6: 111 | J6: 64 | K6: 175 | L6: 404 | M6: 95 | N6: 13 | O6: 62 | P6: 170 | Q6: 90 | R6: 14 | S6: 57 | T6: 161 | U6: 100 | V6: 19 | W6: 56 | X6: 175 | Y6: 85 | Z6: 8 | AA6: 63 | AB6: 156 | AC6: 44931 | AD6: Thu | AE6: 1 | AF6: NI | AG6: 31 | AH6: 166 | AI6: 72 | AJ6: 53 | AK6: 125 | AL6: 322 | AM6: 80 | AN6: 10 | AO6: 30 | AP6: 120 | AQ6: 65 | AR6: 5 | AS6: 28 | AT6: 98 | AU6: 84 | AV6: 9 | AW6: 32 | AX6: 125 | AY6: 61 | AZ6: 6 | BA6: 26 | BB6: 93
A7: 44932 | B7: Fri | C7: 4 | D7: DX | E7: 138 | F7: 74 | G7: 83 | H7: 157 | I7: 119 | J7: 51 | K7: 170 | L7: 465 | M7: 107 | N7: 15 | O7: 69 | P7: 191 | Q7: 80 | R7: 6 | S7: 39 | T7: 125 | U7: 80 | V7: 9 | W7: 81 | X7: 170 | Y7: 107 | Z7: 12 | AA7: 27 | AB7: 146 | AC7: 44932 | AD7: Fri | AE7: 3 | AF7: NI | AG7: 43 | AH7: 190 | AI7: 87 | AJ7: 46 | AK7: 133 | AL7: 366 | AM7: 66 | AN7: 7 | AO7: 44 | AP7: 117 | AQ7: 43 | AR7: 14 | AS7: 24 | AT7: 81 | AU7: 79 | AV7: 16 | AW7: 38 | AX7: 133 | AY7: 30 | AZ7: 5 | BA7: 30 | BB7: 65
A8: 44933 | B8: Sat | C8: 4 | D8: DX | E8: 84 | F8: 87 | G8: 79 | H8: 166 | I8: 119 | J8: 60 | K8: 179 | L8: 429 | M8: 122 | N8: 12 | O8: 42 | P8: 176 | Q8: 86 | R8: 13 | S8: 56 | T8: 155 | U8: 101 | V8: 11 | W8: 67 | X8: 179 | Y8: 107 | Z8: 14 | AA8: 31 | AB8: 152 | AC8: 44933 | AD8: Sat | AE8: 3 | AF8: NI | AG8: 32 | AH8: 208 | AI8: 109 | AJ8: 50 | AK8: 159 | AL8: 399 | AM8: 94 | AN8: 6 | AO8: 53 | AP8: 153 | AQ8: 50 | AR8: 9 | AS8: 34 | AT8: 93 | AU8: 95 | AV8: 12 | AW8: 52 | AX8: 159 | AY8: 49 | AZ8: 3 | BA8: 35 | BB8: 87
A9: 44934 | B9: Sun | C9: 1 | D9: DX | E9: 92 | F9: 78 | G9: 91 | H9: 169 | I9: 99 | J9: 36 | K9: 135 | L9: 396 | M9: 122 | N9: 18 | O9: 45 | P9: 185 | Q9: 111 | R9: 18 | S9: 48 | T9: 177 | U9: 68 | V9: 13 | W9: 54 | X9: 135 | Y9: 165 | Z9: 23 | AA9: 39 | AB9: 227 | AC9: 44934 | AD9: Sun | AE9: 2 | AF9: NI | AG9: 43 | AH9: 284 | AI9: 95 | AJ9: 25 | AK9: 120 | AL9: 447 | AM9: 101 | AN9: 12 | AO9: 27 | AP9: 140 | AQ9: 63 | AR9: 5 | AS9: 22 | AT9: 90 | AU9: 80 | AV9: 16 | AW9: 24 | AX9: 120 | AY9: 84 | AZ9: 1 | BA9: 25 | BB9: 110
A10: 44935 | B10: Mon | C10: 1 | D10: DX | E10: 117 | F10: 82 | G10: 58 | H10: 140 | I10: 106 | J10: 32 | K10: 138 | L10: 395 | M10: 95 | N10: 14 | O10: 50 | P10: 159 | Q10: 62 | R10: 15 | S10: 54 | T10: 131 | U10: 75 | V10: 15 | W10: 48 | X10: 138 | Y10: 82 | Z10: 14 | AA10: 56 | AB10: 152 | AC10: 44935 | AD10: Mon | AE10: 2 | AF10: NI | AG10: 43 | AH10: 197 | AI10: 84 | AJ10: 52 | AK10: 136 | AL10: 376 | AM10: 72 | AN10: 9 | AO10: 30 | AP10: 111 | AQ10: 54 | AR10: 4 | AS10: 37 | AT10: 95 | AU10: 82 | AV10: 12 | AW10: 42 | AX10: 136 | AY10: 44 | AZ10: 1 | BA10: 25 | BB10: 70
A11: 44936 | B11: Tue | C11: 3 | D11: DX | E11: 83 | F11: 67 | G11: 75 | H11: 142 | I11: 102 | J11: 68 | K11: 170 | L11: 395 | M11: 99 | N11: 15 | O11: 58 | P11: 172 | Q11: 80 | R11: 11 | S11: 61 | T11: 152 | U11: 85 | V11: 16 | W11: 69 | X11: 170 | Y11: 94 | Z11: 10 | AA11: 50 | AB11: 154 | AC11: 44936 | AD11: Tue | AE11: 4 | AF11: NI | AG11: 37 | AH11: 192 | AI11: 128 | AJ11: 51 | AK11: 179 | AL11: 408 | AM11: 88 | AN11: 10 | AO11: 58 | AP11: 156 | AQ11: 55 | AR11: 9 | AS11: 26 | AT11: 90 | AU11: 103 | AV11: 8 | AW11: 68 | AX11: 179 | AY11: 40 | AZ11: 11 | BA11: 16 | BB11: 67
A12: 44937 | B12: Wed | C12: 3 | D12: DX | E12: 92 | F12: 66 | G12: 74 | H12: 140 | I12: 87 | J12: 56 | K12: 143 | L12: 375 | M12: 106 | N12: 18 | O12: 59 | P12: 183 | Q12: 104 | R12: 17 | S12: 49 | T12: 170 | U12: 63 | V12: 15 | W12: 65 | X12: 143 | Y12: 147 | Z12: 20 | AA12: 43 | AB12: 210 | AC12: 44937 | AD12: Wed | AE12: 4 | AF12: NI | AG12: 44 | AH12: 293 | AI12: 118 | AJ12: 51 | AK12: 169 | AL12: 506 | AM12: 104 | AN12: 11 | AO12: 38 | AP12: 153 | AQ12: 79 | AR12: 6 | AS12: 26 | AT12: 111 | AU12: 110 | AV12: 13 | AW12: 46 | AX12: 169 | AY12: 73 | AZ12: 4 | BA12: 18 | BB12: 95
A13: 44938 | B13: Thu | C13: 2 | D13: DX | E13: 143 | F13: 95 | G13: 70 | H13: 165 | I13: 121 | J13: 51 | K13: 172 | L13: 480 | M13: 142 | N13: 7 | O13: 61 | P13: 210 | Q13: 116 | R13: 15 | S13: 41 | T13: 172 | U13: 100 | V13: 9 | W13: 63 | X13: 172 | Y13: 158 | Z13: 13 | AA13: 39 | AB13: 210 | AC13: 44938 | AD13: Thu | AE13: 1 | AF13: NI | AG13: 57 | AH13: 242 | AI13: 100 | AJ13: 34 | AK13: 134 | AL13: 433 | AM13: 103 | AN13: 7 | AO13: 45 | AP13: 155 | AQ13: 66 | AR13: 9 | AS13: 33 | AT13: 108 | AU13: 85 | AV13: 12 | AW13: 37 | AX13: 134 | AY13: 84 | AZ13: 4 | BA13: 41 | BB13: 129
